<?xml version="1.0" ?>
<robot name="myrobot">
   <link name="base_link">
      <visual>
         <geometry>
            <box size="0.57 0.53 1.5"/>
         </geometry>
         <origin rpy="0.0 -0.0 0.0" xyz="0.0 0.0 0.75"/>
      </visual>
      <collision>
         <geometry>
            <box size="0.57 0.53 1.5"/>
         </geometry>
         <origin rpy="0.0 -0.0 0.0" xyz="0.0 0.0 0.75"/>
      </collision>
   </link>
   <link name="door_link">
      <visual>
         <geometry>
            <box size="0.03 0.53 0.67"/>
         </geometry>
         <origin rpy="0.0 -0.0 0.0" xyz="0.0 0.265 0.335"/>
      </visual>
      <collision>
         <geometry>
            <box size="0.03 0.53 0.67"/>
         </geometry>
         <origin rpy="0.0 -0.0 0.0" xyz="0.0 0.265 0.335"/>
      </collision>
   </link>
   <link name="handle_link">
      <visual>
         <geometry>
            <box size="0.05 0.02 0.2"/>
         </geometry>
         <origin rpy="0.0 -0.0 0.0" xyz="0.0 0.0 0.0"/>
      </visual>
   </link>
   <joint name="door_joint" type="revolute">
      <parent link="base_link"/>
      <child link="door_link"/>
      <axis xyz="0 0 1"/>
      <origin rpy="0 0 0" xyz="-0.285 -0.265 0.83"/>
      <limit effort="1.0" lower="0.0" upper="2.0" velocity="2.0"/>
   </joint>
   <joint name="handle_joint" type="fixed">
      <parent link="door_link"/>
      <child link="handle_link"/>
      <axis xyz="0 0 1"/>
      <origin rpy="0 0 0" xyz="-0.03 0.49 0.25"/>
   </joint>
</robot>
